Workbook

Sheet Dashboard
B2: NGX EQUITY SCREENING FRAMEWORK
B3: Growth · Dividend Income · Value — Nigerian Exchange · May 2026
B5: MARKET CONTEXT
B6: NGX Market Cap | C6: ₦156 Trillion | D6: USD ~113 billion
B7: Listed Equities | C7: 146 companies | D7: Main Board + Growth Board
B8: Risk-Free Rate | C8: ~18 – 20% | D8: 91-day T-bill yield — equity hurdle rate
B9: CPI Inflation | C9: ~30%+ | D9: Real return bar — equity must clear this
B10: CBN Policy Rate | C10: ~27% | D10: High-rate environment; leverage is expensive
B12: GROWTH · 3–7 yr | E12: DIVIDEND · Any | H12: VALUE · 2–5 yr
B13: Revenue Growth YoY | C13: ≥ 25% | E13: Dividend Yield | F13: ≥ 8% (pref ≥ 12%) | H13: P / E Ratio | I13: ≤ 6x bank / ≤ 10x ind.
B14: EPS Growth YoY | C14: ≥ 20% | E14: Payout Ratio | F14: 20 – 60% | H14: P / B Ratio | I14: ≤ 1.0x (target ≤ 0.8x)
B15: Return on Equity | C15: ≥ 20% | E15: FCF / Div. Cover | F15: ≥ 1.5x | H15: ROE Quality Gate | I15: ≥ 12%
B16: Net Profit Margin | C16: ≥ 15 / 20% bank | E16: Dividend CAGR 5yr | F16: ≥ 10% | H16: Margin of Safety | I16: ≥ 30% below intrinsic
B17: Debt / Equity | C17: ≤ 1.5x | E17: Consecutive Div. Yrs | F17: ≥ 5 years | H17: Net Debt / EBITDA | I17: ≤ 2.5x
B18: PEG Ratio | C18: ≤ 1.0x | E18: EPS / DPS Cover | F18: ≥ 1.5x | H18: Interest Coverage | I18: ≥ 3.0x
B19: FCF Margin | C19: ≥ 10% | E19: Net Debt / EBITDA | F19: ≤ 2.0x | H19: CAR (banks) | I19: ≥ 15%
B23: UNIVERSAL NGX SCREENING RULES — Applied to all three strategies
B24: Inflation Hurdle | C24: All equities must offer credible path to real returns exceeding ~30% inflation (yield + capital appreciation)
B25: FX Adjustment | C25: Strip out 2024–25 naira revaluation gains from EPS and revenue. Only organic volume and price growth counts
B26: Liquidity Floor | C26: Minimum average daily trading volume ≥ ₦50M. Illiquid positions cannot be sized or exited appropriately
B27: Governance | C27: Verify NGX/SEC compliance status; independent directors majority; no outstanding regulatory sanctions
B28: Reporting Timeliness | C28: Results filed within 90 days of period-end. Late filers are penalised — delays frequently conceal problems
B29: Auditor Quality | C29: Prefer Big 4 or top-tier Nigerian firms (KPMG, PwC, Deloitte, EY). Unexplained auditor changes = investigate
B31: LAST ANALYZED STOCK — Auto-updated from Company Analyzer
B32: ='Company Analyzer'!C8 | G32: =Classification!B7
B34: Growth | E34: Dividend | H34: Value
B35: =Classification!C39 | E35: =Classification!D39 | H35: =Classification!E39
B36: Enter financials in the Company Analyzer sheet. Results update here automatically.

Sheet Company Analyzer
B2: COMPANY ANALYZER
B3: Enter figures from the annual report. Blue cells = your inputs. Black cells = calculated.
B4: Inputs are in ₦ Billions unless the field states otherwise.
B6: 1. COMPANY INFORMATION
B7: Field | C7: Input | D7: Reference / Notes
B8: Company Name | C8: Guaranty Trust Holding Co. | D8: Full name as listed on NGX
B9: NGX Ticker | C9: GTCO | D9: e.g. GTCO, ZENITHBANK, DANGCEM
B10: Sector | C10: Banking | D10: Banking | Consumer Goods | Industrial | Oil & Gas | Telecoms | Healthcare | Insurance
B11: Reporting Period | C11: FY 2025 | D11: e.g. FY 2025 or Q1 2026
B12: Share Price (₦) | C12: 130 | D12: Current market price in Naira
B13: Shares Outstanding (millions) | C13: 29,431 | D13: Total shares in millions — from notes or NGX filings
B15: 2. INCOME STATEMENT (₦ Billions)
B16: Metric | C16: Current Year | D16: Prior Year | E16: Where to find it
B17: Revenue / Gross Earnings | C17: 1,230 | D17: 1,004 | E17: Top line — P&L (use Gross Earnings for banks)
B18: Gross Profit | C18: 900 | D18: 730 | E18: Revenue minus Cost of Goods Sold — P&L
B19: Operating Profit (EBIT) | C19: 680 | D19: 540 | E19: Earnings Before Interest & Tax — P&L
B20: Interest Expense | C20: 85 | D20: 72 | E20: Finance costs / Interest paid — P&L notes
B21: Profit Before Tax (PBT) | C21: 1,230 | D21: 1,004 | E21: PBT line — use group consolidated figures
B22: Profit After Tax (PAT / Net Profit) | C22: 865 | D22: 1,020 | E22: Bottom-line net profit attributable to shareholders
B23: Earnings Per Share — EPS (₦) | C23: 25.43 | D23: 35.44 | E23: Basic EPS — P&L or EPS note, not diluted
B25: 3. BALANCE SHEET (₦ Billions)
B26: Metric | C26: Current Year | D26: Prior Year | E26: Where to find it
B27: Total Assets | C27: 17,800 | D27: 15,700 | E27: Total Assets — Balance Sheet
B28: Total Shareholders' Equity | C28: 3,400 | D28: 2,990 | E28: Total Equity / Shareholders' Funds — Balance Sheet
B29: Total Interest-Bearing Debt | C29: 950 | D29: 810 | E29: Loans + Bonds + Borrowings (exclude customer deposits for banks)
B30: Cash & Cash Equivalents | C30: 1,200 | D30: 980 | E30: Cash + short-term investments — Balance Sheet
B31: Current Assets | C31: 5,400 | D31: 4,200 | E31: Total current assets — Balance Sheet (non-bank only)
B32: Current Liabilities | C32: 3,800 | D32: 3,100 | E32: Total current liabilities — Balance Sheet (non-bank only)
B33: Book Value Per Share (₦) | C33: 115.52 | D33: 101.60 | E33: Total Equity ÷ Shares Outstanding — or from notes
B34: Capital Adequacy Ratio (%) | C34: 43.8 | D34: 38.5 | E34: BANKS ONLY — regulatory capital disclosures
B35: Stage 3 / NPL Ratio (%) | C35: 3.4 | D35: 5.0 | E35: BANKS ONLY — credit risk note
B37: 4. CASH FLOW & DIVIDEND DATA (₦ Billions unless stated)
B38: Metric | C38: Current Value | D38: Prior / Historical | E38: Where to find it
B39: Operating Free Cash Flow (₦B) | C39: 750 | D39: 820 | E39: Cash from Operations minus Capex — Cash Flow Statement
B40: Total Dividends Paid (₦B) | C40: 375 | D40: 237 | E40: Cash paid as dividends — Financing section of Cash Flow
B41: Dividend Per Share — DPS (₦) | C41: 12.76 | D41: 8.03 | E41: DPS declared for the period — from dividend announcement
B42: DPS Year -2 (₦) | C42: 5.50 | D42: 4.50 | E42: DPS two years prior — for CAGR calculation
B43: DPS Year -3 (₦) | C43: 4.50 | D43: 3.80 | E43: DPS three years prior — for CAGR calculation
B44: DPS Year -4 (₦) | C44: 3.80 | D44: 3.20 | E44: DPS four years prior — for CAGR calculation
B45: Consecutive Dividend Years | C45: 10 | E45: How many consecutive years dividends have been paid
...

Sheet Classification
B2: ='Company Analyzer'!C8
B3: ='Company Analyzer'!C10&" | Ticker: "&'Company Analyzer'!C9&" | Price: ₦"&TEXT('Company Analyzer'!C12,"#,##0.00")&" | Period: "&'Company Analyzer'!C11
B4: Auto-classification from financials in Company Analyzer. Black = formula. Green = cross-sheet link.
B6: CLASSIFICATION
B7: =_xludf.TEXTJOIN(" + ",TRUE,IF(OR(C39>=0.7),"GROWTH",""),IF(OR(D39>=0.7),"DIVIDEND",""),IF(OR(E39>=0.7),"VALUE",""))
B10: =IF(AND(C39<0.7,D39<0.7,E39<0.7),"DOES NOT MEET CRITERIA FOR ANY STRATEGY","")
B11: ="Growth: "&TEXT(C39,"0%")&" ("&TEXT(C37,"0.0")&" / "&C38&") Dividend: "&TEXT(D39,"0%")&" ("&TEXT(D37,"0.0")&" / "&D38&") Value: "&TEXT(E39,"0%")&" ("&TEXT(E37,"0.0")&" / "&E38&")"
B12: Criterion | C12: Growth | D12: Dividend | E12: Value
B13: Revenue Growth ≥ 25% | C13: =IF('Company Analyzer'!C52>=0.25,"PASS","FAIL") | D13: ="—" | E13: ="—"
B14: EPS Growth ≥ 20% | C14: =IF('Company Analyzer'!C53>=0.2,"PASS","FAIL") | D14: ="—" | E14: ="—"
B15: Return on Equity (20% / 15% / 12%) | C15: =IF('Company Analyzer'!C56>=0.2,"PASS","FAIL") | D15: =IF('Company Analyzer'!C56>=0.15,"PASS","FAIL") | E15: =IF('Company Analyzer'!C56>=0.12,"PASS","FAIL")
B16: Net Profit Margin ≥ 15% (non-bank) / 20% (bank) | C16: =IF(OR('Company Analyzer'!C10="Banking",'Company Analyzer'!C10="Insurance"),IF('Company Analyzer'!C55>=0.2,"PASS","FAIL"),IF('Company Analyzer'!C55>=0.15,"PASS","FAIL")) | D16: ="—" | E16: ="—"
B17: Debt / Equity ≤ 1.5x / 2.0x / 2.5x | C17: =IF(OR('Company Analyzer'!C10="Banking",'Company Analyzer'!C10="Insurance"),"N/A (Bank)",IF('Company Analyzer'!C58<=1.5,"PASS","FAIL")) | D17: =IF(OR('Company Analyzer'!C10="Banking",'Company Analyzer'!C10="Insurance"),"N/A (Bank)",IF('Company Analyzer'!C58<=2,"PASS","FAIL")) | E17: =IF(OR('Company Analyzer'!C10="Banking",'Company Analyzer'!C10="Insurance"),"N/A (Bank)",IF('Company Analyzer'!C58<=2.5,"PASS","FAIL"))
B18: Dividend Yield ≥ 8% (floor) / ≥ 12% (preferred) | C18: ="—" | D18: =IF('Company Analyzer'!C64>=0.12,"PASS",IF('Company Analyzer'!C64>=0.08,"PARTIAL","FAIL")) | E18: ="—"
B19: Payout Ratio 20 – 60% | C19: ="—" | D19: =IF(AND('Company Analyzer'!C65>=0.2,'Company Analyzer'!C65<=0.6),"PASS","FAIL") | E19: ="—"
B20: FCF / Dividend Cover ≥ 1.5x | C20: ="—" | D20: =IF('Company Analyzer'!C66>=1.5,"PASS","FAIL") | E20: ="—"
B21: EPS / DPS Cover ≥ 1.5x | C21: ="—" | D21: =IF('Company Analyzer'!C67>=1.5,"PASS","FAIL") | E21: ="—"
B22: Dividend CAGR ≥ 10% (4-year) | C22: ="—" | D22: =IF('Company Analyzer'!C68>=0.1,"PASS","FAIL") | E22: ="—"
B23: Consecutive Dividend Years ≥ 5 | C23: ="—" | D23: =IF('Company Analyzer'!C69>=5,"PASS","FAIL") | E23: ="—"
B24: No Missed Dividends (past 5 yrs) | C24: ="—" | D24: =IF('Company Analyzer'!C48=1,"PASS","FAIL") | E24: ="—"
B25: P / E Ratio ≤ 6x (bank) / ≤ 10x (industrial) | C25: ="—" | D25: ="—" | E25: =IF(OR('Company Analyzer'!C10="Banking",'Company Analyzer'!C10="Insurance"),IF('Company Analyzer'!C62<=6,"PASS","FAIL"),IF('Company Analyzer'!C62<=10,"PASS","FAIL"))
B26: P / B Ratio ≤ 1.0x (target ≤ 0.8x) | C26: ="—" | D26: ="—" | E26: =IF('Company Analyzer'!C63<=0.8,"PASS",IF('Company Analyzer'!C63<=1,"PARTIAL","FAIL"))
B27: Net Debt / EBITDA ≤ 2.0x / ≤ 2.5x | C27: ="—" | D27: =IF('Company Analyzer'!C59<=2,"PASS","FAIL") | E27: =IF('Company Analyzer'!C59<=2.5,"PASS","FAIL")
B28: Interest Coverage ≥ 4x (D) / ≥ 3x (V) | C28: ="—" | D28: =IF(OR('Company Analyzer'!C10="Banking",'Company Analyzer'!C10="Insurance"),"N/A (Bank)",IF('Company Analyzer'!C60>=4,"PASS","FAIL")) | E28: =IF(OR('Company Analyzer'!C10="Banking",'Company Analyzer'!C10="Insurance"),"N/A (Bank)",IF('Company Analyzer'!C60>=3,"PASS","FAIL"))
B29: Current Ratio ≥ 1.2x (non-bank) | C29: ="—" | D29: ="—" | E29: =IF(OR('Company Analyzer'!C10="Banking",'Company Analyzer'!C10="Insurance"),"N/A (Bank)",IF('Company Analyzer'!C61>=1.2,"PASS","FAIL"))
B30: Capital Adequacy ≥ 15% (banks only) | C30: ="—" | D30: ="—" | E30: =IF(OR('Company Analyzer'!C10="Banking",'Company Analyzer'!C10="Insurance"),IF('Company Analyzer'!C71>=15,"PASS","FAIL"),"N/A (Non-Bank)")
B31: Stage 3 / NPL ≤ 5% (banks only) | C31: ="—" | D31: ="—" | E31: =IF(OR('Company Analyzer'!C10="Banking",'Company Analyzer'!C10="Insurance"),IF('Company Analyzer'!C72<=5,"PASS","FAIL"),"N/A (Non-Bank)")
B32: Daily Liquidity ≥ ₦50M (all strategies) | C32: =IF('Company Analyzer'!C70>=50,"PASS","FAIL") | D32: =IF('Company Analyzer'!C70>=50,"PASS","FAIL") | E32: =IF('Company Analyzer'!C70>=50,"PASS","FAIL")
B33: Big 4 Auditor | C33: =IF('Company Analyzer'!C47=1,"PASS","FAIL") | D33: =IF('Company Analyzer'!C47=1,"PASS","FAIL") | E33: =IF('Company Analyzer'!C47=1,"PASS","FAIL")
B35: SCORES
B36: Metric | C36: Growth | D36: Dividend | E36: Value
B37: Criteria Passed | C37: =COUNTIF(C13:C33,"PASS")+COUNTIF(C13:C33,"PARTIAL")*0.5 | D37: =COUNTIF(D13:D33,"PASS")+COUNTIF(D13:D33,"PARTIAL")*0.5 | E37: =COUNTIF(E13:E33,"PASS")+COUNTIF(E13:E33,"PARTIAL")*0.5
B38: Relevant Criteria (excl. —) | C38: =COUNTIF(C13:C33,"<>—") | D38: =COUNTIF(D13:D33,"<>—") | E38: =COUNTIF(E13:E33,"<>—")
B39: Score % | C39: =IFERROR(C37/C38,0) | D39: =IFERROR(D37/D38,0) | E39: =IFERROR(E37/E38,0)
B40: Verdict | C40: =IF(C39>=0.85,"STRONG PASS",IF(C39>=0.7,"PASS",IF(C39>=0.5,"BORDERLINE","FAIL"))) | D40: =IF(D39>=0.85,"STRONG PASS",IF(D39>=0.7,"PASS",IF(D39>=0.5,"BORDERLINE","FAIL"))) | E40: =IF(E39>=0.85,"STRONG PASS",IF(E39>=0.7,"PASS",IF(E39>=0.5,"BORDERLINE","FAIL")))

Sheet Criteria Reference
B2: CRITERIA REFERENCE — Full Threshold Definitions
B3: All screening thresholds used by the Classification engine, with context and rationale.
B5: Strategy | C5: Growth Threshold | D5: Dividend Threshold | E5: Value Threshold | F5: Context & Rationale
B6: ALL
B7: Daily Liquidity (₦M) | C7: ≥ 50 | D7: ≥ 50 | E7: ≥ 50 | F7: Illiquid positions cannot be sized or exited. Only screen stocks with ≥ ₦50M average daily turnover.
B8: Big 4 Auditor | C8: Yes | D8: Yes | E8: Yes | F8: Prefer KPMG, PwC, Deloitte, or EY Nigeria. Unexplained auditor changes warrant deep investigation.
B9: GROWTH
B10: Revenue Growth YoY | C10: ≥ 25% | D10: — | E10: — | F10: Floor to outpace ~30% inflation. Require 3+ consecutive years. Strip FX revaluation — organic growth only.
B11: EPS Growth YoY | C11: ≥ 20% | D11: — | E11: — | F11: Revenue growing without EPS growth = margin erosion. Check 3yr EPS CAGR to smooth one-off gains.
B12: ALL
B13: Return on Equity | C13: ≥ 20% | D13: ≥ 15% | E13: ≥ 12% | F13: Critical quality gate for all strategies. Must be sustained. Banks: target ≥25%. Single spike is insufficient.
B14: GROWTH
B15: Net Profit Margin | C15: ≥ 15 / 20% | D15: — | E15: — | F15: Rising margins on rising revenue = exponential profit compounding. 20% threshold for banks, 15% for others.
B16: Debt / Equity (non-bank) | C16: ≤ 1.5x | D16: ≤ 2.0x | E16: ≤ 2.5x | F16: Nigeria's 20%+ interest rates make leverage expensive. For banks, screen via Capital Adequacy Ratio instead.
B17: DIVIDEND
B18: Dividend Yield | C18: — | D18: ≥ 8 / 12% | E18: — | F18: T-bills yield ~18–20% risk-free. Target ≥12% for pure income. 8% acceptable only with capital gain upside.
B19: Payout Ratio | C19: — | D19: 20 – 60% | E19: — | F19: Below 20%: hoarding cash. Above 60%: payout may be unsustainable. Sweet spot: 30–55%.
B20: FCF / Dividend Cover | C20: — | D20: ≥ 1.5x | E20: — | F20: Dividends must be backed by real operating cash, not debt. Below 1.0x = funded from borrowings.
B21: EPS / DPS Cover | C21: — | D21: ≥ 1.5x | E21: — | F21: Dividend Cover = EPS ÷ DPS. Cover of 1.5x means earnings are 50% above the payout — a safety buffer.
B22: Dividend CAGR (4-yr) | C22: — | D22: ≥ 10% | E22: — | F22: A stagnant dividend loses real value vs 30% inflation. GTCO's 5yr CAGR is 29% — the NGX benchmark.
B23: Consecutive Dividend Years | C23: — | D23: ≥ 5 yrs | E23: — | F23: Require 5 unbroken payment years. Many NGX companies cut dividends during FX crises (2016, 2023).
B24: VALUE
B25: P / E Ratio | C25: — | D25: — | E25: ≤ 6x / 10x | F25: NGX banks trade at 2–8x. P/E ≤ 5x for a profitable, well-capitalised bank is a compelling entry. Avoid P/E < 1x.
B26: P / B Ratio | C26: — | D26: — | E26: ≤ 1.0x | F26: Trading below book = buying assets for less than stated value. REQUIRE ROE ≥ 12% simultaneously — else value trap.
B27: ALL
B28: Net Debt / EBITDA | C28: — | D28: ≤ 2.0x | E28: ≤ 2.5x | F28: With policy rate at ~27%, debt payments drain cash flow needed for dividends or re-rating. Net cash = ideal.
B29: Interest Coverage (non-bank) | C29: — | D29: ≥ 4x | E29: ≥ 3x | F29: At 20%+ rates, thin coverage means debt service consumes operating profit. Below 2x = high cut risk.
B30: VALUE
B31: Current Ratio (non-bank) | C31: — | D31: — | E31: ≥ 1.2x | F31: Ensures near-term liquidity. A cheap stock with current ratio < 1.0x may be cheap due to a liquidity crisis.
B32: CAR (banks only) | C32: — | D32: — | E32: ≥ 15% | F32: Bank near regulatory minimum CAR may need dilutive capital raise. Require CAR well above 10–15% CBN floor.
B33: Stage 3 / NPL (banks only) | C33: — | D33: — | E33: ≤ 5% | F33: Rising NPLs are a bank value trap. Require Stage 3 loans stable or declining and ≥80% provision coverage.
B35: SECTOR BENCHMARKS — P/E ranges, dividend targets, and key metric by sector
B36: Sector | C36: Growth P/E | D36: Value P/E | E36: Div. Yield Target | F36: Key Watch Metric
B37: Banking — Tier 1 | C37: 3 – 8x | D37: ≤ 4x | E37: ≥ 10% | F37: ROE ≥ 25% · Cost-to-Income < 40% · Fee income growing faster than interest income
B38: Banking — Tier 2 | C38: 2 – 5x | D38: ≤ 3x | E38: ≥ 7% | F38: NPL trend · CAR vs. minimum · Liquidity coverage ratio
B39: Consumer Goods / FMCG | C39: 8 – 18x | D39: ≤ 8x | E39: ≥ 5% | F39: Gross margin trend · Volume vs. price growth split · FX import exposure
B40: Industrial / Cement | C40: 6 – 14x | D40: ≤ 7x | E40: ≥ 4% | F40: EBITDA margin · Energy cost as % of revenue · Capacity utilisation
B41: Oil & Gas | C41: 5 – 12x | D41: ≤ 6x | E41: ≥ 5% | F41: Production growth · 2P reserves · Lifting cost per barrel · FX hedging
B42: Telecoms / ICT | C42: 8 – 16x | D42: ≤ 8x | E42: ≥ 6% | F42: ARPU growth · Data revenue % · Capex-to-revenue declining
B43: Healthcare / Pharma | C43: 10 – 20x | D43: ≤ 10x | E43: ≥ 3% | F43: Domestic production % rising · Regulatory approvals pipeline
...

Sheet FI Dashboard
B2: FIXED INCOME & BOND MARKET DASHBOARD — Nigeria
B3: FMDQ · DMO · CBN · Auto-updated: 2026-05-06 16:58 · FMDQ prices: manual entry required (paid subscription)
B5: RATE ENVIRONMENT — Update from Data Guide instructions
B6: Instrument | C6: Current Rate | D6: Prior Month | E6: Change bps | F6: Source | G6: Last Updated | H6: Notes
B7: CBN Monetary Policy Rate | C7: =CBNRates!C7 | D7: =CBNRates!D7 | E7: =IFERROR((CBNRates!C7-CBNRates!D7)*10000,"—") | F7: CBN MPC | G7: Manual | H7: Benchmark rate — all yields priced relative to this
B8: NTB 91-Day (T-Bill) | C8: =CBNRates!C8 | D8: =CBNRates!D8 | E8: =IFERROR((CBNRates!C8-CBNRates!D8)*10000,"—") | F8: CBN / DMO | G8: Manual | H8: Risk-free rate; equity hurdle rate benchmark
B9: NTB 182-Day | C9: =CBNRates!C9 | D9: =CBNRates!D9 | E9: =IFERROR((CBNRates!C9-CBNRates!D9)*10000,"—") | F9: CBN / DMO | G9: Manual
B10: NTB 364-Day | C10: =CBNRates!C10 | D10: =CBNRates!D10 | E10: =IFERROR((CBNRates!C10-CBNRates!D10)*10000,"—") | F10: CBN / DMO | G10: Manual
B11: FGN Bond 2-Year | C11: =CBNRates!C11 | D11: =CBNRates!D11 | E11: =IFERROR((CBNRates!C11-CBNRates!D11)*10000,"—") | F11: FMDQ / DMO | G11: Manual | H11: Short end of sovereign curve
B12: FGN Bond 5-Year | C12: =CBNRates!C12 | D12: =CBNRates!D12 | E12: =IFERROR((CBNRates!C12-CBNRates!D12)*10000,"—") | F12: FMDQ / DMO | G12: Manual
B13: FGN Bond 10-Year | C13: =CBNRates!C13 | D13: =CBNRates!D13 | E13: =IFERROR((CBNRates!C13-CBNRates!D13)*10000,"—") | F13: FMDQ / DMO | G13: Manual | H13: 14.95% as at Apr 30 2026 (TradingEconomics)
B14: FGN Bond 15-Year | C14: =CBNRates!C14 | D14: =CBNRates!D14 | E14: =IFERROR((CBNRates!C14-CBNRates!D14)*10000,"—") | F14: FMDQ / DMO | G14: Manual
B15: FGN Bond 20-Year | C15: =CBNRates!C15 | D15: =CBNRates!D15 | E15: =IFERROR((CBNRates!C15-CBNRates!D15)*10000,"—") | F15: FMDQ / DMO | G15: Manual
B16: FGN Bond 30-Year | C16: =CBNRates!C16 | D16: =CBNRates!D16 | E16: =IFERROR((CBNRates!C16-CBNRates!D16)*10000,"—") | F16: FMDQ / DMO | G16: Manual
B17: Corp Bond Avg Coupon (IG) | C17: =CBNRates!C17 | D17: =CBNRates!D17 | E17: =IFERROR((CBNRates!C17-CBNRates!D17)*10000,"—") | F17: FMDQ | G17: Manual | H17: Investment grade — avg coupon rate
B18: CP Avg Discount Rate | C18: =CBNRates!C18 | D18: =CBNRates!D18 | E18: =IFERROR((CBNRates!C18-CBNRates!D18)*10000,"—") | F18: FMDQ | G18: Manual | H18: ~22.38% avg in 2025; trending down in 2026
B19: Inflation (CPI) | C19: =CBNRates!C19 | D19: =CBNRates!D19 | E19: =IFERROR((CBNRates!C19-CBNRates!D19)*10000,"—") | F19: NBS | G19: Manual | H19: Sets the real return bar for all instruments
B21: SOVEREIGN YIELD CURVE SNAPSHOT (auto-populates from Yield Curve sheet)
B22: Tenor | C22: Yield % | D22: vs 91d T-bill | E22: vs Inflation | F22: Real Yield | G22: Category | H22: Signal
B23: 91 Days (T-Bill) | C23: ='Yield Curve'!C7 | D23: =IFERROR((C23-CBNRates!C8)*10000,"—") | E23: =IFERROR((C23-CBNRates!C19)*10000,"—") | F23: =IFERROR(C23-CBNRates!C19,"—") | G23: Short | H23: =IF(C23="","—",IF(C23>CBNRates!C19,"Real +ve","Real -ve"))
B24: 182 Days | C24: ='Yield Curve'!C8 | D24: =IFERROR((C24-CBNRates!C8)*10000,"—") | E24: =IFERROR((C24-CBNRates!C19)*10000,"—") | F24: =IFERROR(C24-CBNRates!C19,"—") | G24: Short | H24: =IF(C24="","—",IF(C24>CBNRates!C19,"Real +ve","Real -ve"))
B25: 364 Days | C25: ='Yield Curve'!C9 | D25: =IFERROR((C25-CBNRates!C8)*10000,"—") | E25: =IFERROR((C25-CBNRates!C19)*10000,"—") | F25: =IFERROR(C25-CBNRates!C19,"—") | G25: Short | H25: =IF(C25="","—",IF(C25>CBNRates!C19,"Real +ve","Real -ve"))
B26: 2 Year | C26: ='Yield Curve'!C10 | D26: =IFERROR((C26-CBNRates!C8)*10000,"—") | E26: =IFERROR((C26-CBNRates!C19)*10000,"—") | F26: =IFERROR(C26-CBNRates!C19,"—") | G26: Medium | H26: =IF(C26="","—",IF(C26>CBNRates!C19,"Real +ve","Real -ve"))
B27: 3 Year | C27: ='Yield Curve'!C11 | D27: =IFERROR((C27-CBNRates!C8)*10000,"—") | E27: =IFERROR((C27-CBNRates!C19)*10000,"—") | F27: =IFERROR(C27-CBNRates!C19,"—") | G27: Medium | H27: =IF(C27="","—",IF(C27>CBNRates!C19,"Real +ve","Real -ve"))
B28: 5 Year | C28: ='Yield Curve'!C12 | D28: =IFERROR((C28-CBNRates!C8)*10000,"—") | E28: =IFERROR((C28-CBNRates!C19)*10000,"—") | F28: =IFERROR(C28-CBNRates!C19,"—") | G28: Medium | H28: =IF(C28="","—",IF(C28>CBNRates!C19,"Real +ve","Real -ve"))
B29: 7 Year | C29: ='Yield Curve'!C13 | D29: =IFERROR((C29-CBNRates!C8)*10000,"—") | E29: =IFERROR((C29-CBNRates!C19)*10000,"—") | F29: =IFERROR(C29-CBNRates!C19,"—") | G29: Medium | H29: =IF(C29="","—",IF(C29>CBNRates!C19,"Real +ve","Real -ve"))
B30: 10 Year | C30: ='Yield Curve'!C14 | D30: =IFERROR((C30-CBNRates!C8)*10000,"—") | E30: =IFERROR((C30-CBNRates!C19)*10000,"—") | F30: =IFERROR(C30-CBNRates!C19,"—") | G30: Long | H30: =IF(C30="","—",IF(C30>CBNRates!C19,"Real +ve","Real -ve"))
B31: 15 Year | C31: ='Yield Curve'!C15 | D31: =IFERROR((C31-CBNRates!C8)*10000,"—") | E31: =IFERROR((C31-CBNRates!C19)*10000,"—") | F31: =IFERROR(C31-CBNRates!C19,"—") | G31: Long | H31: =IF(C31="","—",IF(C31>CBNRates!C19,"Real +ve","Real -ve"))
B32: 20 Year | C32: ='Yield Curve'!C16 | D32: =IFERROR((C32-CBNRates!C8)*10000,"—") | E32: =IFERROR((C32-CBNRates!C19)*10000,"—") | F32: =IFERROR(C32-CBNRates!C19,"—") | G32: Long | H32: =IF(C32="","—",IF(C32>CBNRates!C19,"Real +ve","Real -ve"))
B33: 30 Year | C33: ='Yield Curve'!C17 | D33: =IFERROR((C33-CBNRates!C8)*10000,"—") | E33: =IFERROR((C33-CBNRates!C19)*10000,"—") | F33: =IFERROR(C33-CBNRates!C19,"—") | G33: Long | H33: =IF(C33="","—",IF(C33>CBNRates!C19,"Real +ve","Real -ve"))
B35: MARKET SUMMARY — Key counts from tracker sheets
B36: Instrument Class | C36: Issues Tracked | D36: Avg Yield / Rate | E36: Total Value ₦B | F36: Nearest Maturity | G36: Source
B37: FGN Bonds (Active) | C37: ='FGN Bonds'!B4 | D37: ='FGN Bonds'!C4 | E37: ='FGN Bonds'!D4 | F37: ='FGN Bonds'!E4 | G37: DMO
B38: NTBs (91/182/364d) | C38: ='Yield Curve'!H4 | D38: ='Yield Curve'!H5 | E38: ='Yield Curve'!H6 | F38: ='Yield Curve'!H7 | G38: DMO Auctions
B39: Corporate Bonds | C39: ='Corporate Bonds'!B4 | D39: ='Corporate Bonds'!C4 | E39: ='Corporate Bonds'!D4 | F39: ='Corporate Bonds'!E4 | G39: FMDQ / NGX
B40: Commercial Papers | C40: ='Commercial Papers'!B4 | D40: ='Commercial Papers'!C4 | E40: ='Commercial Papers'!D4 | F40: ='Commercial Papers'!E4 | G40: FMDQ
B41: Eurobonds (USD-denominated) | C41: =Eurobonds!B4 | D41: =Eurobonds!C4 | E41: =Eurobonds!D4 | F41: =Eurobonds!E4 | G41: Eurobonds sheet
B44: Auto-refreshed: 18 May 2026 18:17 · NTBs: CBN API (latest: 03/11/2026) · 10Y FGN: 14.958% · Eurobonds: DMO Excel (to 2026-05-15) · NGX prices: manual (X-DataPortal required)

Sheet CBNRates
B2: RATE INPUTS — Update this sheet. All FI Dashboard and tracker sheets pull from here.
B3: Blue cells = your inputs. Source instructions in the Data Guide sheet.
B5: CURRENT & PRIOR MONTH RATES (enter as decimals: 18% = 0.18)
B6: Instrument | C6: Current | D6: Prior Month | E6: Source URL / Where to find | F6: Notes
B7: CBN MPR | C7: 0.265 | D7: 0.265 | E7: CBN MPC press release cbn.gov.ng/monetary | F7: Monetary Policy Rate — benchmark
B8: NTB 91-Day | C8: 0.1595 | D8: 0.1595 | E8: cbn.gov.ng/rates/GovtSecurities.html | F8: Primary market stop rate
B9: NTB 182-Day | C9: 0.1665 | D9: 0.1665 | E9: cbn.gov.ng/rates/GovtSecurities.html
B10: NTB 364-Day | C10: 0.1672 | D10: 0.1672 | E10: cbn.gov.ng/rates/GovtSecurities.html
B11: FGN Bond 2-Year | C11: 0.165 | D11: 0.172 | E11: DMO weekly bond highlights dmo.gov.ng
B12: FGN Bond 5-Year | C12: 0.08 | D12: 0.08 | E12: DMO weekly bond highlights dmo.gov.ng
B13: FGN Bond 10-Year | C13: 0.14958 | D13: 0.14957 | E13: tradingeconomics.com or DMO FMDQ closing prices | F13: 14.95% as at Apr 30 2026
B14: FGN Bond 15-Year | C14: 0.1545 | D14: 0.1545 | E14: DMO weekly bond highlights
B15: FGN Bond 20-Year | C15: 0.1569 | D15: 0.1569 | E15: DMO weekly bond highlights
B16: FGN Bond 30-Year | C16: 0.157 | D16: 0.157 | E16: DMO weekly bond highlights
B17: Corp Bond Avg (IG) | C17: 0.18 | D17: 0.18 | E17: FMDQ listings page fmdqgroup.com | F17: Investment grade avg coupon
B18: CP Avg Discount Rate | C18: 0.2238 | D18: 0.22 | E18: FMDQ monthly report fmdqgroup.com | F18: Gross; subtract 10% WHT for net
B19: Inflation (CPI) | C19: 0.1569 | D19: 0.1569 | E19: NBS nigerianstat.gov.ng | F19: Most recent headline CPI
B21: Enter rates as decimals (0.18 = 18%). Update monthly or after each DMO auction.
B42: Auto-refreshed: 18 May 2026 18:17 · Sources: CBN API (NTB/FGN) · TradingEconomics (10Y/MPR/CPI) · DMO Eurobond Excel

Sheet Yield Curve
B2: YIELD CURVE & TREASURY BILLS TRACKER
B3: Sovereign yield curve + NTB auction results. Pulls from CBN Rates sheet. | H3: =COUNTA(C7:C17)
H4: =COUNTA(B21:B28)
B5: SOVEREIGN YIELD CURVE (data feeds FI Dashboard) | H5: =IFERROR(AVERAGE(G21:G28),0)
B6: Tenor | C6: Yield % | D6: Real Yield | E6: vs MPR bps | F6: vs Inflation bps | G6: Curve Shape | H6: =IFERROR(SUM(F21:F28),0)
B7: 91 Days (T-Bill) | C7: =CBNRates!C8 | D7: =IFERROR(C7-CBNRates!C19,"—") | E7: =IFERROR((C7-CBNRates!C7)*10000,"—") | F7: =IFERROR((C7-CBNRates!C19)*10000,"—") | H7: =IFERROR(_xludf.MINIFS(H21:H28,H21:H28,">"&TODAY()),"—")
B8: 182 Days | C8: =CBNRates!C9 | D8: =IFERROR(C8-CBNRates!C19,"—") | E8: =IFERROR((C8-CBNRates!C7)*10000,"—") | F8: =IFERROR((C8-CBNRates!C19)*10000,"—")
B9: 364 Days | C9: =CBNRates!C10 | D9: =IFERROR(C9-CBNRates!C19,"—") | E9: =IFERROR((C9-CBNRates!C7)*10000,"—") | F9: =IFERROR((C9-CBNRates!C19)*10000,"—")
B10: 2 Year | C10: =CBNRates!C11 | D10: =IFERROR(C10-CBNRates!C19,"—") | E10: =IFERROR((C10-CBNRates!C7)*10000,"—") | F10: =IFERROR((C10-CBNRates!C19)*10000,"—")
B11: 3 Year | C11: =CBNRates!C11 | D11: =IFERROR(C11-CBNRates!C19,"—") | E11: =IFERROR((C11-CBNRates!C7)*10000,"—") | F11: =IFERROR((C11-CBNRates!C19)*10000,"—")
B12: 5 Year | C12: =CBNRates!C12 | D12: =IFERROR(C12-CBNRates!C19,"—") | E12: =IFERROR((C12-CBNRates!C7)*10000,"—") | F12: =IFERROR((C12-CBNRates!C19)*10000,"—")
B13: 7 Year | C13: =CBNRates!C12 | D13: =IFERROR(C13-CBNRates!C19,"—") | E13: =IFERROR((C13-CBNRates!C7)*10000,"—") | F13: =IFERROR((C13-CBNRates!C19)*10000,"—")
B14: 10 Year | C14: =CBNRates!C13 | D14: =IFERROR(C14-CBNRates!C19,"—") | E14: =IFERROR((C14-CBNRates!C7)*10000,"—") | F14: =IFERROR((C14-CBNRates!C19)*10000,"—")
B15: 15 Year | C15: =CBNRates!C14 | D15: =IFERROR(C15-CBNRates!C19,"—") | E15: =IFERROR((C15-CBNRates!C7)*10000,"—") | F15: =IFERROR((C15-CBNRates!C19)*10000,"—")
B16: 20 Year | C16: =CBNRates!C15 | D16: =IFERROR(C16-CBNRates!C19,"—") | E16: =IFERROR((C16-CBNRates!C7)*10000,"—") | F16: =IFERROR((C16-CBNRates!C19)*10000,"—")
B17: 30 Year | C17: =CBNRates!C16 | D17: =IFERROR(C17-CBNRates!C19,"—") | E17: =IFERROR((C17-CBNRates!C7)*10000,"—") | F17: =IFERROR((C17-CBNRates!C19)*10000,"—")
B19: NTB AUCTION TRACKER — Enter results after each DMO auction
B20: Auction Date | C20: Tenor | D20: Offered ₦B | E20: Subscribed ₦B | F20: Allotted ₦B | G20: Stop Rate % | H20: Maturity Date
B21: 46329 | C21: 364 Day | D21: 600 | E21: 2567.1813 | F21: 731.81149 | G21: 0.1672 | H21: 46092
B22: 46329 | C22: 182 Day | D22: 150 | E22: 82.336627 | F22: 71.36872 | G22: 0.1665 | H22: 46275
B23: 46329 | C23: 91 Day | D23: 100 | E23: 131.11674 | F23: 130.74132 | G23: 0.1595 | H23: 46184
B24: 46329 | C24: 364 Day | D24: 600 | E24: 2567.1813 | F24: 731.81149 | G24: 0.1672 | H24: 46092
B25: 46329 | C25: 182 Day | D25: 150 | E25: 82.336627 | F25: 71.36872 | G25: 0.1665 | H25: 46275
B26: 46329 | C26: 91 Day | D26: 100 | E26: 131.11674 | F26: 130.74132 | G26: 0.1595 | H26: 46184
B27: 46329 | C27: 364 Day | D27: 600 | E27: 2567.1813 | F27: 731.81149 | G27: 0.1672 | H27: 46694
B28: 46329 | C28: 182 Day | D28: 150 | E28: 82.336627 | F28: 71.36872 | G28: 0.1665 | H28: 46275
B29: 46329 | C29: 91 Day | D29: 100 | E29: 131.11674 | F29: 130.74132 | G29: 0.1595 | H29: 46184
B30: 46329 | C30: 364 Day | D30: 600 | E30: 2567.1813 | F30: 731.81149 | G30: 0.1672 | H30: 46694
B31: 46329 | C31: 182 Day | D31: 150 | E31: 82.336627 | F31: 71.36872 | G31: 0.1665 | H31: 46275
B32: 46329 | C32: 91 Day | D32: 100 | E32: 131.11674 | F32: 130.74132 | G32: 0.1595 | H32: 46184
... B40: 46080 | C40: 364 Day | D40: 100 | E40: 165 | F40: 100 | G40: 0.207 | H40: 46444

Sheet FGN Bonds
B2: FGN BOND TRACKER — Active Federal Government of Nigeria Bonds
B3: Source: DMO weekly highlights (dmo.gov.ng) + FMDQ closing prices. Blue cells = manual update.
B4: =COUNTA(B7:B19)-COUNTBLANK(B7:B19) | C4: =IFERROR(AVERAGEIF(G7:G19,">0",G7:G19),0) | D4: =IFERROR(SUM(H7:H19),0) | E4: =IFERROR(_xludf.MINIFS(E7:E19,E7:E19,">"&TODAY()),"—")
B5: ACTIVE FGN BONDS — Re-opening series · Source: DMO.gov.ng · Update after each monthly auction
B6: Bond Name / ISIN | C6: Coupon % | D6: Issue Date | E6: Maturity Date | F6: Tenor (yrs) | G6: Current Yield % | H6: Outstanding ₦B | I6: Last Auction Stop Rate | J6: Bid-Cover | K6: Benchmark?
B7: 17.945% FGN AUG 2030 | C7: 17.945% | D7: 44060 | E7: 47712 | F7: =IFERROR(DATEDIF(D7,E7,"Y"),"—") | G7: 0.163 | H7: 1250 | I7: 16.00% | J7: 1.2 | K7: Yes
B8: 17.95% FGN JUN 2032 | C8: 17.95% | D8: 44732 | E8: 48385 | F8: =IFERROR(DATEDIF(D8,E8,"Y"),"—") | G8: 0.165 | H8: 980 | I8: 16.15% | J8: 1.4 | K8: Yes
B9: 22.60% FGN JAN 2035 | C9: 22.60% | D9: 45677 | E9: 49329 | F9: =IFERROR(DATEDIF(D9,E9,"Y"),"—") | G9: 0.1659 | H9: 2100 | I9: 17.52% | J9: 2.5 | K9: Yes
B10: 14.55% FGN APR 2029 | C10: 14.55% | D10: 43570 | E10: 47223 | F10: =IFERROR(DATEDIF(D10,E10,"Y"),"—") | G10: 0.165 | H10: 760 | I10: — | J10: — | K10: No
B11: 12.50% FGN MAR 2035 | C11: 12.50% | D11: 43913 | E11: 49391 | F11: =IFERROR(DATEDIF(D11,E11,"Y"),"—") | G11: 0.1659 | H11: 850 | I11: — | J11: — | K11: No
B12: 16.39% FGN JAN 2022 | C12: 16.39% | D12: 42023 | E12: 50059 | F12: =IFERROR(DATEDIF(D12,E12,"Y"),"—") | G12: 0.17 | H12: 620 | I12: — | J12: — | K12: No
B13: FGN FEB 2031 (Reopened) | C13: ~17.62% | D13: 46073 | E13: 47899 | F13: =IFERROR(DATEDIF(D13,E13,"Y"),"—") | G13: 0.1762 | H13: 1680 | I13: 17.62% | J13: 2.5 | K13: Yes
B14: FGN FEB 2034 (Reopened) | C14: ~15.50% | D14: 46073 | E14: 48995 | F14: =IFERROR(DATEDIF(D14,E14,"Y"),"—") | G14: 0.155 | H14: 524 | I14: 15.50% | J14: 1.3 | K14: Yes
B15: FGN MAY 2033 (Reopened) | C15: ~16.64% | D15: 46101 | E15: 48719 | F15: =IFERROR(DATEDIF(D15,E15,"Y"),"—") | G15: 0.1664 | H15: 486 | I15: 16.64% | J15: 1.2 | K15: No
B16: FGN APR 2036 Sukuk | C16: Ijarah | D16: 44375 | E16: 49854 | F16: =IFERROR(DATEDIF(D16,E16,"Y"),"—") | G16: — | H16: 162.6 | I16: — | J16: — | K16: No
B17: FGN Green Bond 2027 | C17: 13.98% | D17: 43087 | E17: 46739 | F17: =IFERROR(DATEDIF(D17,E17,"Y"),"—") | G17: 0.162 | H17: 10.69 | I17: — | J17: — | K17: No
B19: BOND ANALYTICS (auto-calculated from inputs above · assumes semi-annual coupons)
B20: Bond Name | C20: Years to Maturity | D20: Modified Duration | E20: Convexity | F20: Price @ Par | G20: Spread vs 10Y FGN bps | H20: Spread vs T-Bill bps | I20: Real Yield % | J20: WHT Net % | K20: Buy Signal
B21: =B7 | C21: =IFERROR(YEARFRAC(TODAY(),E7,1),"—") | D21: =IFERROR(DURATION(TODAY(),E7,C7,G7,2,1),"—") | E21: =IFERROR(C21*(C21+1)/((1+G7/2)^2),"—") | F21: =IFERROR(PRICE(TODAY(),E7,C7,G7,100,2,1),"—") | G21: =IFERROR((G7-CBNRates!C13)*10000,"—") | H21: =IFERROR((G7-CBNRates!C13)*10000,"—") | I21: =IFERROR(G7-CBNRates!C19,"—") | J21: =IFERROR(G7*0.9,"—") | K21: =IFERROR(IF(G7>CBNRates!C19,"Real +ve","Real -ve"),"—")
B22: =B8 | C22: =IFERROR(YEARFRAC(TODAY(),E8,1),"—") | D22: =IFERROR(DURATION(TODAY(),E8,C8,G8,2,1),"—") | E22: =IFERROR(C22*(C22+1)/((1+G8/2)^2),"—") | F22: =IFERROR(PRICE(TODAY(),E8,C8,G8,100,2,1),"—") | G22: =IFERROR((G8-CBNRates!C13)*10000,"—") | H22: =IFERROR((G8-CBNRates!C13)*10000,"—") | I22: =IFERROR(G8-CBNRates!C19,"—") | J22: =IFERROR(G8*0.9,"—") | K22: =IFERROR(IF(G8>CBNRates!C19,"Real +ve","Real -ve"),"—")
B23: =B9 | C23: =IFERROR(YEARFRAC(TODAY(),E9,1),"—") | D23: =IFERROR(DURATION(TODAY(),E9,C9,G9,2,1),"—") | E23: =IFERROR(C23*(C23+1)/((1+G9/2)^2),"—") | F23: =IFERROR(PRICE(TODAY(),E9,C9,G9,100,2,1),"—") | G23: =IFERROR((G9-CBNRates!C13)*10000,"—") | H23: =IFERROR((G9-CBNRates!C13)*10000,"—") | I23: =IFERROR(G9-CBNRates!C19,"—") | J23: =IFERROR(G9*0.9,"—") | K23: =IFERROR(IF(G9>CBNRates!C19,"Real +ve","Real -ve"),"—")
B24: =B10 | C24: =IFERROR(YEARFRAC(TODAY(),E10,1),"—") | D24: =IFERROR(DURATION(TODAY(),E10,C10,G10,2,1),"—") | E24: =IFERROR(C24*(C24+1)/((1+G10/2)^2),"—") | F24: =IFERROR(PRICE(TODAY(),E10,C10,G10,100,2,1),"—") | G24: =IFERROR((G10-CBNRates!C13)*10000,"—") | H24: =IFERROR((G10-CBNRates!C13)*10000,"—") | I24: =IFERROR(G10-CBNRates!C19,"—") | J24: =IFERROR(G10*0.9,"—") | K24: =IFERROR(IF(G10>CBNRates!C19,"Real +ve","Real -ve"),"—")
B25: =B11 | C25: =IFERROR(YEARFRAC(TODAY(),E11,1),"—") | D25: =IFERROR(DURATION(TODAY(),E11,C11,G11,2,1),"—") | E25: =IFERROR(C25*(C25+1)/((1+G11/2)^2),"—") | F25: =IFERROR(PRICE(TODAY(),E11,C11,G11,100,2,1),"—") | G25: =IFERROR((G11-CBNRates!C13)*10000,"—") | H25: =IFERROR((G11-CBNRates!C13)*10000,"—") | I25: =IFERROR(G11-CBNRates!C19,"—") | J25: =IFERROR(G11*0.9,"—") | K25: =IFERROR(IF(G11>CBNRates!C19,"Real +ve","Real -ve"),"—")
B26: =B12 | C26: =IFERROR(YEARFRAC(TODAY(),E12,1),"—") | D26: =IFERROR(DURATION(TODAY(),E12,C12,G12,2,1),"—") | E26: =IFERROR(C26*(C26+1)/((1+G12/2)^2),"—") | F26: =IFERROR(PRICE(TODAY(),E12,C12,G12,100,2,1),"—") | G26: =IFERROR((G12-CBNRates!C13)*10000,"—") | H26: =IFERROR((G12-CBNRates!C13)*10000,"—") | I26: =IFERROR(G12-CBNRates!C19,"—") | J26: =IFERROR(G12*0.9,"—") | K26: =IFERROR(IF(G12>CBNRates!C19,"Real +ve","Real -ve"),"—")
B27: =B13 | C27: =IFERROR(YEARFRAC(TODAY(),E13,1),"—") | D27: =IFERROR(DURATION(TODAY(),E13,C13,G13,2,1),"—") | E27: =IFERROR(C27*(C27+1)/((1+G13/2)^2),"—") | F27: =IFERROR(PRICE(TODAY(),E13,C13,G13,100,2,1),"—") | G27: =IFERROR((G13-CBNRates!C13)*10000,"—") | H27: =IFERROR((G13-CBNRates!C13)*10000,"—") | I27: =IFERROR(G13-CBNRates!C19,"—") | J27: =IFERROR(G13*0.9,"—") | K27: =IFERROR(IF(G13>CBNRates!C19,"Real +ve","Real -ve"),"—")
B28: =B14 | C28: =IFERROR(YEARFRAC(TODAY(),E14,1),"—") | D28: =IFERROR(DURATION(TODAY(),E14,C14,G14,2,1),"—") | E28: =IFERROR(C28*(C28+1)/((1+G14/2)^2),"—") | F28: =IFERROR(PRICE(TODAY(),E14,C14,G14,100,2,1),"—") | G28: =IFERROR((G14-CBNRates!C13)*10000,"—") | H28: =IFERROR((G14-CBNRates!C13)*10000,"—") | I28: =IFERROR(G14-CBNRates!C19,"—") | J28: =IFERROR(G14*0.9,"—") | K28: =IFERROR(IF(G14>CBNRates!C19,"Real +ve","Real -ve"),"—")
B29: =B15 | C29: =IFERROR(YEARFRAC(TODAY(),E15,1),"—") | D29: =IFERROR(DURATION(TODAY(),E15,C15,G15,2,1),"—") | E29: =IFERROR(C29*(C29+1)/((1+G15/2)^2),"—") | F29: =IFERROR(PRICE(TODAY(),E15,C15,G15,100,2,1),"—") | G29: =IFERROR((G15-CBNRates!C13)*10000,"—") | H29: =IFERROR((G15-CBNRates!C13)*10000,"—") | I29: =IFERROR(G15-CBNRates!C19,"—") | J29: =IFERROR(G15*0.9,"—") | K29: =IFERROR(IF(G15>CBNRates!C19,"Real +ve","Real -ve"),"—")
B30: =B16 | C30: =IFERROR(YEARFRAC(TODAY(),E16,1),"—") | D30: =IFERROR(DURATION(TODAY(),E16,C16,G16,2,1),"—") | E30: =IFERROR(C30*(C30+1)/((1+G16/2)^2),"—") | F30: =IFERROR(PRICE(TODAY(),E16,C16,G16,100,2,1),"—") | G30: =IFERROR((G16-CBNRates!C13)*10000,"—") | H30: =IFERROR((G16-CBNRates!C13)*10000,"—") | I30: =IFERROR(G16-CBNRates!C19,"—") | J30: =IFERROR(G16*0.9,"—") | K30: =IFERROR(IF(G16>CBNRates!C19,"Real +ve","Real -ve"),"—")
B31: =B17 | C31: =IFERROR(YEARFRAC(TODAY(),E17,1),"—") | D31: =IFERROR(DURATION(TODAY(),E17,C17,G17,2,1),"—") | E31: =IFERROR(C31*(C31+1)/((1+G17/2)^2),"—") | F31: =IFERROR(PRICE(TODAY(),E17,C17,G17,100,2,1),"—") | G31: =IFERROR((G17-CBNRates!C13)*10000,"—") | H31: =IFERROR((G17-CBNRates!C13)*10000,"—") | I31: =IFERROR(G17-CBNRates!C19,"—") | J31: =IFERROR(G17*0.9,"—") | K31: =IFERROR(IF(G17>CBNRates!C19,"Real +ve","Real -ve"),"—")

Sheet Corporate Bonds
B2: CORPORATE BOND TRACKER — FMDQ & NGX Listed
B3: Source: FMDQ Listings page (fmdqgroup.com/category/listings-and-quotations) · NGX Bond Board · Blue cells = manual input.
B4: =COUNTA(B7:B24)-COUNTBLANK(B7:B24) | C4: =IFERROR(AVERAGEIF(K7:K24,">0",K7:K24),0) | D4: =IFERROR(SUM(I7:I24),0) | E4: =IFERROR(_xludf.MINIFS(E7:E24,E7:E24,">"&TODAY()),"—")
B5: ACTIVE CORPORATE BONDS — Update from FMDQ portal after each new listing
B6: Issuer / Bond Name | C6: Sector | D6: Issue Date | E6: Maturity | F6: Coupon % | G6: Rating | H6: Prog. Size ₦B | I6: Amount Raised ₦B | J6: Listed On | K6: Current YTM % | L6: Spread vs FGN 10Y bps
B7: Eat & Go Finance SPV Ser.1 | C7: Consumer | D7: 45323 | E7: 46419 | F7: 18.00% | G7: BBB- | H7: 5 | I7: 1.2 | J7: FMDQ | K7: 0.185 | L7: =IFERROR(IF(K7="","—",(K7-CBNRates!C13)*10000),"—")
B8: Mixta Real Estate Ser.3 | C8: Real Estate | D8: 45092 | E8: 46188 | F8: 18.50% | G8: BBB- | H8: 10 | I8: 8.5 | J8: FMDQ | K8: — | L8: =IFERROR(IF(K8="","—",(K8-CBNRates!C13)*10000),"—")
B9: Coronation Merchant Bank Bond | C9: Banking | D9: 45536 | E9: 46631 | F9: 20.00% | G9: A- | H9: 30 | I9: 30 | J9: FMDQ | K9: 0.198 | L9: =IFERROR(IF(K9="","—",(K9-CBNRates!C13)*10000),"—")
B10: LAPO Microfinance Bank Bond | C10: Finance | D10: 45352 | E10: 46447 | F10: 19.50% | G10: BB+ | H10: 5 | I10: 5 | J10: FMDQ | K10: 0.195 | L10: =IFERROR(IF(K10="","—",(K10-CBNRates!C13)*10000),"—")
B11: FBN Finance Sub-Bond | C11: Banking | D11: 44501 | E11: 48153 | F11: 9.75% USD | G11: — | H11: 300M USD | I11: 300M USD | J11: FMDQ | K11: — | L11: =IFERROR(IF(K11="","—",(K11-CBNRates!C13)*10000),"—")
B12: Access Bank Holdco Bond | C12: Banking | D12: 45078 | E12: 47635 | F12: 18.50% | G12: A- | H12: 75 | I12: 75 | J12: NGX | K12: 0.188 | L12: =IFERROR(IF(K12="","—",(K12-CBNRates!C13)*10000),"—")
B13: UBA Sub-Debt Bond | C13: Banking | D13: 45170 | E13: 48823 | F13: 15.75% USD | G13: BB | H13: 500M USD | I13: 500M USD | J13: FMDQ | K13: — | L13: =IFERROR(IF(K13="","—",(K13-CBNRates!C13)*10000),"—")
L14: =IFERROR(IF(K14="","—",(K14-CBNRates!C13)*10000),"—")
L15: =IFERROR(IF(K15="","—",(K15-CBNRates!C13)*10000),"—")
L16: =IFERROR(IF(K16="","—",(K16-CBNRates!C13)*10000),"—")
L17: =IFERROR(IF(K17="","—",(K17-CBNRates!C13)*10000),"—")
L18: =IFERROR(IF(K18="","—",(K18-CBNRates!C13)*10000),"—")
L19: =IFERROR(IF(K19="","—",(K19-CBNRates!C13)*10000),"—")
L20: =IFERROR(IF(K20="","—",(K20-CBNRates!C13)*10000),"—")
L21: =IFERROR(IF(K21="","—",(K21-CBNRates!C13)*10000),"—")
B23: CORPORATE BOND SCREENING — Is the spread worth the credit risk?
B24: Issuer | C24: Coupon % | D24: Maturity | E24: Rating | F24: Spread vs FGN bps | G24: Spread vs T-Bill bps | H24: Real Yield % | I24: WHT Net % | J24: Duration (yrs) | K24: Risk-Adj Score | L24: Notes
B25: =B7 | C25: =F7 | D25: =E7 | E25: =G7 | F25: =IFERROR(IF(K7="","—",(K7-CBNRates!C13)*10000),"—") | G25: =IFERROR(IF(K7="","—",(K7-CBNRates!C8)*10000),"—") | H25: =IFERROR(IF(K7="","—",K7-CBNRates!C19),"—") | I25: =IFERROR(IF(K7="","—",K7*0.9),"—") | J25: =IFERROR(DURATION(TODAY(),E7,F7,K7,2,1),"—") | K25: =IFERROR(IF(OR(K7="",J25=""),"—",(K7-CBNRates!C13)/J25*10000),"—")
B26: =B8 | C26: =F8 | D26: =E8 | E26: =G8 | F26: =IFERROR(IF(K8="","—",(K8-CBNRates!C13)*10000),"—") | G26: =IFERROR(IF(K8="","—",(K8-CBNRates!C8)*10000),"—") | H26: =IFERROR(IF(K8="","—",K8-CBNRates!C19),"—") | I26: =IFERROR(IF(K8="","—",K8*0.9),"—") | J26: =IFERROR(DURATION(TODAY(),E8,F8,K8,2,1),"—") | K26: =IFERROR(IF(OR(K8="",J26=""),"—",(K8-CBNRates!C13)/J26*10000),"—")
B27: =B9 | C27: =F9 | D27: =E9 | E27: =G9 | F27: =IFERROR(IF(K9="","—",(K9-CBNRates!C13)*10000),"—") | G27: =IFERROR(IF(K9="","—",(K9-CBNRates!C8)*10000),"—") | H27: =IFERROR(IF(K9="","—",K9-CBNRates!C19),"—") | I27: =IFERROR(IF(K9="","—",K9*0.9),"—") | J27: =IFERROR(DURATION(TODAY(),E9,F9,K9,2,1),"—") | K27: =IFERROR(IF(OR(K9="",J27=""),"—",(K9-CBNRates!C13)/J27*10000),"—")
B28: =B10 | C28: =F10 | D28: =E10 | E28: =G10 | F28: =IFERROR(IF(K10="","—",(K10-CBNRates!C13)*10000),"—") | G28: =IFERROR(IF(K10="","—",(K10-CBNRates!C8)*10000),"—") | H28: =IFERROR(IF(K10="","—",K10-CBNRates!C19),"—") | I28: =IFERROR(IF(K10="","—",K10*0.9),"—") | J28: =IFERROR(DURATION(TODAY(),E10,F10,K10,2,1),"—") | K28: =IFERROR(IF(OR(K10="",J28=""),"—",(K10-CBNRates!C13)/J28*10000),"—")
B29: =B11 | C29: =F11 | D29: =E11 | E29: =G11 | F29: =IFERROR(IF(K11="","—",(K11-CBNRates!C13)*10000),"—") | G29: =IFERROR(IF(K11="","—",(K11-CBNRates!C8)*10000),"—") | H29: =IFERROR(IF(K11="","—",K11-CBNRates!C19),"—") | I29: =IFERROR(IF(K11="","—",K11*0.9),"—") | J29: =IFERROR(DURATION(TODAY(),E11,F11,K11,2,1),"—") | K29: =IFERROR(IF(OR(K11="",J29=""),"—",(K11-CBNRates!C13)/J29*10000),"—")
B30: =B12 | C30: =F12 | D30: =E12 | E30: =G12 | F30: =IFERROR(IF(K12="","—",(K12-CBNRates!C13)*10000),"—") | G30: =IFERROR(IF(K12="","—",(K12-CBNRates!C8)*10000),"—") | H30: =IFERROR(IF(K12="","—",K12-CBNRates!C19),"—") | I30: =IFERROR(IF(K12="","—",K12*0.9),"—") | J30: =IFERROR(DURATION(TODAY(),E12,F12,K12,2,1),"—") | K30: =IFERROR(IF(OR(K12="",J30=""),"—",(K12-CBNRates!C13)/J30*10000),"—")
B31: =B13 | C31: =F13 | D31: =E13 | E31: =G13 | F31: =IFERROR(IF(K13="","—",(K13-CBNRates!C13)*10000),"—") | G31: =IFERROR(IF(K13="","—",(K13-CBNRates!C8)*10000),"—") | H31: =IFERROR(IF(K13="","—",K13-CBNRates!C19),"—") | I31: =IFERROR(IF(K13="","—",K13*0.9),"—") | J31: =IFERROR(DURATION(TODAY(),E13,F13,K13,2,1),"—") | K31: =IFERROR(IF(OR(K13="",J31=""),"—",(K13-CBNRates!C13)/J31*10000),"—")

Sheet Commercial Papers
B2: COMMERCIAL PAPERS TRACKER — FMDQ Quoted
B3: Source: FMDQ portal · Avg discount rate 2025: ~22.38% · WHT 10% applies from Jan 2025 · Blue = manual input
B4: =COUNTA(B7:B23)-COUNTBLANK(B7:B23) | C4: =IFERROR(AVERAGEIF(H7:H23,">0",H7:H23),0) | D4: =IFERROR(SUM(G7:G23),0) | E4: =IFERROR(_xludf.MINIFS(F7:F23,F7:F23,">"&TODAY()),"—")
B5: ACTIVE COMMERCIAL PAPERS — Add new CPs as they are quoted on FMDQ
B6: Issuer / CP Name | C6: Sector | D6: Issue Date | E6: Tenor (days) | F6: Maturity Date | G6: Face Value ₦B | H6: Gross Disc Rate % | I6: Net Rate (after WHT %) | J6: Prog Size ₦B | K6: Rating | L6: Series
B7: Access Bank — CP Programme | C7: Banking | D7: 46054 | E7: 265 | F7: 46318 | G7: 82.82 | H7: 0.215 | I7: =IFERROR(H7*0.9,"—") | J7: 300 | K7: A1+ | L7: Ser. 5
B8: Dangote Sugar Refinery CP | C8: Consumer | D8: 46037 | E8: 270 | F8: 46307 | G8: 84.01 | H8: 0.22 | I8: =IFERROR(H8*0.9,"—") | J8: 100 | K8: A- | L8: Ser. 8
B9: Stanbic IBTC Capital CP | C9: Banking | D9: 46063 | E9: 180 | F9: 46243 | G9: 25.15 | H9: 0.205 | I9: =IFERROR(H9*0.9,"—") | J9: 50 | K9: A1+ | L9: Ser. 4
B10: Citibank Nigeria CP | C10: Banking | D10: 46042 | E10: 265 | F10: 46307 | G10: 46.73 | H10: 0.21 | I10: =IFERROR(H10*0.9,"—") | J10: 300 | K10: A1+ | L10: Ser. 4
B11: MTN Nigeria CP Ser.14 | C11: Telecoms | D11: 46068 | E11: 270 | F11: 46338 | G11: 27.5 | H11: 0.208 | I11: =IFERROR(H11*0.9,"—") | J11: 200 | K11: A+ | L11: Ser. 14
B12: Dangote Cement CP | C12: Industrial | D12: 46082 | E12: 180 | F12: 46262 | G12: 41 | H12: 0.212 | I12: =IFERROR(H12*0.9,"—") | J12: 100 | K12: A+ | L12: Ser. 6
B13: Flour Mills Nigeria CP | C13: Consumer | D13: 46047 | E13: 270 | F13: 46317 | G13: 15 | H13: 0.225 | I13: =IFERROR(H13*0.9,"—") | J13: 30 | K13: A- | L13: Ser. 5
B14: FSDH Merchant Bank CP | C14: Banking | D14: 46054 | E14: 180 | F14: 46233 | G14: 5.7 | H14: 0.2 | I14: =IFERROR(H14*0.9,"—") | J14: 40 | K14: A- | L14: Ser. 2
B15: C&I Leasing CP | C15: Industrial | D15: 45931 | E15: 270 | F15: 46201 | G15: 8.14 | H15: 0.245 | I15: =IFERROR(H15*0.9,"—") | J15: 50 | K15: BB+ | L15: Ser. 5
B16: Valency Agro Nigeria CP | C16: Agriculture | D16: 46082 | E16: 180 | F16: 46262 | G16: 22.7 | H16: 0.24 | I16: =IFERROR(H16*0.9,"—") | J16: 30 | K16: BB | L16: Ser. 3
B17: VFD Group CP | C17: Finance | D17: 46068 | E17: 270 | F17: 46338 | G17: 3.5 | H17: 0.25 | I17: =IFERROR(H17*0.9,"—") | J17: 10 | K17: BB | L17: Ser. 2
B18: UACN CP | C18: Consumer | D18: 46032 | E18: 180 | F18: 46211 | G18: 4.2 | H18: 0.235 | I18: =IFERROR(H18*0.9,"—") | J18: 15 | K18: A- | L18: Ser. 3
... B23: NOVA Merchant Bank CP | C23: Banking | D23: 46113 | E23: 180 | F23: 46293 | G23: 8 | H23: 0.225 | I23: =IFERROR(H23*0.9,"—") | J23: 20 | K23: BB+ | L23: Ser. 1
I24: =IFERROR(H24*0.9,"—")
I25: =IFERROR(H25*0.9,"—")
I26: =IFERROR(H26*0.9,"—")
I27: =IFERROR(H27*0.9,"—")
I28: =IFERROR(H28*0.9,"—")
I29: =IFERROR(H29*0.9,"—")
I30: =IFERROR(H30*0.9,"—")
I31: =IFERROR(H31*0.9,"—")
I32: =IFERROR(H32*0.9,"—")
I33: =IFERROR(H33*0.9,"—")
B35: CP ANALYTICS — Return comparison vs. T-Bills and FGN Bonds
B36: Issuer | C36: Tenor (d) | D36: Gross Rate % | E36: Net (WHT) % | F36: vs 91d T-Bill bps | G36: vs 364d T-Bill bps | H36: vs Inflation bps | I36: Real Net Yield % | J36: Days to Mat. | K36: Rating | L36: Inv. Grade?
B37: =B7 | C37: =E7 | D37: =H7 | E37: =I7 | F37: =IFERROR((H7-CBNRates!C8)*10000,"—") | G37: =IFERROR((H7-CBNRates!C10)*10000,"—") | H37: =IFERROR((I7-CBNRates!C19)*10000,"—") | I37: =IFERROR(I7-CBNRates!C19,"—") | J37: =IFERROR(F7-TODAY(),"—") | K37: =K7 | L37: =IF(OR(K7="AAA",K7="AA+",K7="AA",K7="AA-",K7="A+",K7="A",K7="A-",K7="BBB+",K7="BBB",K7="BBB-",K7="A1+",K7="A1",K7="A2"),"Yes","No / Check")
B38: =B8 | C38: =E8 | D38: =H8 | E38: =I8 | F38: =IFERROR((H8-CBNRates!C8)*10000,"—") | G38: =IFERROR((H8-CBNRates!C10)*10000,"—") | H38: =IFERROR((I8-CBNRates!C19)*10000,"—") | I38: =IFERROR(I8-CBNRates!C19,"—") | J38: =IFERROR(F8-TODAY(),"—") | K38: =K8 | L38: =IF(OR(K8="AAA",K8="AA+",K8="AA",K8="AA-",K8="A+",K8="A",K8="A-",K8="BBB+",K8="BBB",K8="BBB-",K8="A1+",K8="A1",K8="A2"),"Yes","No / Check")
B39: =B9 | C39: =E9 | D39: =H9 | E39: =I9 | F39: =IFERROR((H9-CBNRates!C8)*10000,"—") | G39: =IFERROR((H9-CBNRates!C10)*10000,"—") | H39: =IFERROR((I9-CBNRates!C19)*10000,"—") | I39: =IFERROR(I9-CBNRates!C19,"—") | J39: =IFERROR(F9-TODAY(),"—") | K39: =K9 | L39: =IF(OR(K9="AAA",K9="AA+",K9="AA",K9="AA-",K9="A+",K9="A",K9="A-",K9="BBB+",K9="BBB",K9="BBB-",K9="A1+",K9="A1",K9="A2"),"Yes","No / Check")
B40: =B10 | C40: =E10 | D40: =H10 | E40: =I10 | F40: =IFERROR((H10-CBNRates!C8)*10000,"—") | G40: =IFERROR((H10-CBNRates!C10)*10000,"—") | H40: =IFERROR((I10-CBNRates!C19)*10000,"—") | I40: =IFERROR(I10-CBNRates!C19,"—") | J40: =IFERROR(F10-TODAY(),"—") | K40: =K10 | L40: =IF(OR(K10="AAA",K10="AA+",K10="AA",K10="AA-",K10="A+",K10="A",K10="A-",K10="BBB+",K10="BBB",K10="BBB-",K10="A1+",K10="A1",K10="A2"),"Yes","No / Check")
B41: =B11 | C41: =E11 | D41: =H11 | E41: =I11 | F41: =IFERROR((H11-CBNRates!C8)*10000,"—") | G41: =IFERROR((H11-CBNRates!C10)*10000,"—") | H41: =IFERROR((I11-CBNRates!C19)*10000,"—") | I41: =IFERROR(I11-CBNRates!C19,"—") | J41: =IFERROR(F11-TODAY(),"—") | K41: =K11 | L41: =IF(OR(K11="AAA",K11="AA+",K11="AA",K11="AA-",K11="A+",K11="A",K11="A-",K11="BBB+",K11="BBB",K11="BBB-",K11="A1+",K11="A1",K11="A2"),"Yes","No / Check")
B42: =B12 | C42: =E12 | D42: =H12 | E42: =I12 | F42: =IFERROR((H12-CBNRates!C8)*10000,"—") | G42: =IFERROR((H12-CBNRates!C10)*10000,"—") | H42: =IFERROR((I12-CBNRates!C19)*10000,"—") | I42: =IFERROR(I12-CBNRates!C19,"—") | J42: =IFERROR(F12-TODAY(),"—") | K42: =K12 | L42: =IF(OR(K12="AAA",K12="AA+",K12="AA",K12="AA-",K12="A+",K12="A",K12="A-",K12="BBB+",K12="BBB",K12="BBB-",K12="A1+",K12="A1",K12="A2"),"Yes","No / Check")
B43: =B13 | C43: =E13 | D43: =H13 | E43: =I13 | F43: =IFERROR((H13-CBNRates!C8)*10000,"—") | G43: =IFERROR((H13-CBNRates!C10)*10000,"—") | H43: =IFERROR((I13-CBNRates!C19)*10000,"—") | I43: =IFERROR(I13-CBNRates!C19,"—") | J43: =IFERROR(F13-TODAY(),"—") | K43: =K13 | L43: =IF(OR(K13="AAA",K13="AA+",K13="AA",K13="AA-",K13="A+",K13="A",K13="A-",K13="BBB+",K13="BBB",K13="BBB-",K13="A1+",K13="A1",K13="A2"),"Yes","No / Check")
B44: =B14 | C44: =E14 | D44: =H14 | E44: =I14 | F44: =IFERROR((H14-CBNRates!C8)*10000,"—") | G44: =IFERROR((H14-CBNRates!C10)*10000,"—") | H44: =IFERROR((I14-CBNRates!C19)*10000,"—") | I44: =IFERROR(I14-CBNRates!C19,"—") | J44: =IFERROR(F14-TODAY(),"—") | K44: =K14 | L44: =IF(OR(K14="AAA",K14="AA+",K14="AA",K14="AA-",K14="A+",K14="A",K14="A-",K14="BBB+",K14="BBB",K14="BBB-",K14="A1+",K14="A1",K14="A2"),"Yes","No / Check")
B45: =B15 | C45: =E15 | D45: =H15 | E45: =I15 | F45: =IFERROR((H15-CBNRates!C8)*10000,"—") | G45: =IFERROR((H15-CBNRates!C10)*10000,"—") | H45: =IFERROR((I15-CBNRates!C19)*10000,"—") | I45: =IFERROR(I15-CBNRates!C19,"—") | J45: =IFERROR(F15-TODAY(),"—") | K45: =K15 | L45: =IF(OR(K15="AAA",K15="AA+",K15="AA",K15="AA-",K15="A+",K15="A",K15="A-",K15="BBB+",K15="BBB",K15="BBB-",K15="A1+",K15="A1",K15="A2"),"Yes","No / Check")
B46: =B16 | C46: =E16 | D46: =H16 | E46: =I16 | F46: =IFERROR((H16-CBNRates!C8)*10000,"—") | G46: =IFERROR((H16-CBNRates!C10)*10000,"—") | H46: =IFERROR((I16-CBNRates!C19)*10000,"—") | I46: =IFERROR(I16-CBNRates!C19,"—") | J46: =IFERROR(F16-TODAY(),"—") | K46: =K16 | L46: =IF(OR(K16="AAA",K16="AA+",K16="AA",K16="AA-",K16="A+",K16="A",K16="A-",K16="BBB+",K16="BBB",K16="BBB-",K16="A1+",K16="A1",K16="A2"),"Yes","No / Check")
...

Sheet Bond Analytics
B2: BOND ANALYTICS CALCULATOR
B3: Standalone bond pricing and risk calculator. Blue cells = your inputs. Black = computed.
B5: BOND INPUTS
B6: Input | C6: Value | D6: Unit | E6: Description
B7: Settlement Date | C7: =TODAY() | D7: Date | E7: Enter as YYYY-MM-DD or use TODAY()
B8: Maturity Date | C8: 2035-01-20 | D8: Date | E8: Bond maturity — from term sheet
B9: Coupon Rate | C9: 0.2260 | D9: decimal | E9: Annual coupon as decimal (22.60% = 0.2260)
B10: Current Price | C10: 100.00 | D10: ₦ per 100 face | E10: Dirty price from FMDQ or broker
B11: Face Value | C11: 1000000 | D11: ₦ | E11: Face value of the bond (1,000,000 = ₦1m)
B12: Coupon Frequency | C12: 2 | D12: per year | E12: 2 = semi-annual (FGN standard) · 1 = annual
B13: Settlement Basis | C13: 1 | D13: ACT/ACT | E13: 1 = ACT/ACT (ICMA) · 0 = 30/360
B14: Required Yield | C14: 0.1752 | D14: decimal | E14: Your target / hurdle yield (17.52% = 0.1752)
B15: Tax Rate (WHT) | C15: 0.10 | D15: decimal | E15: 10% WHT applies from Jan 2025
B16: Inflation Rate | C16: =CBNRates!C19 | D16: decimal | E16: Auto-pulls from CBN Rates sheet
B18: CALCULATED OUTPUTS (auto-updates as you change inputs)
B19: Output | C19: Value | D19: Unit | E19: Interpretation
B20: Years to Maturity | C20: =IFERROR(YEARFRAC(C7,C8,1),"—") | D20: years | E20: Remaining life of the bond from today
B21: Yield to Maturity (YTM) | C21: =IFERROR(YIELD(C7,C8,C9,C10,100,C12,C13),"—") | D21: decimal | E21: Internal rate of return if held to maturity — primary return metric
B22: YTM (annualised %) | C22: =IFERROR(YIELD(C7,C8,C9,C10,100,C12,C13),"—") | D22: %
B23: Price at Required Yield | C23: =IFERROR(PRICE(C7,C8,C9,C14,100,C12,C13)*C11/100,"—") | D23: ₦ | E23: Fair value if market yield = your required yield
B24: Macaulay Duration | C24: =IFERROR(DURATION(C7,C8,C9,YIELD(C7,C8,C9,C10,100,C12,C13),C12,C13),"—") | D24: years | E24: Weighted average time to receive cash flows — interest rate sensitivity proxy
B25: Modified Duration | C25: =IFERROR(MDURATION(C7,C8,C9,YIELD(C7,C8,C9,C10,100,C12,C13),C12,C13),"—") | D25: years | E25: % price change for 1% change in yield. Higher = more interest rate risk
B26: DV01 (₦ per ₦1M face) | C26: =IFERROR(MDURATION(C7,C8,C9,YIELD(C7,C8,C9,C10,100,C12,C13),C12,C13)*C10/100*C11*0.0001,"—") | D26: ₦ | E26: Price change for 1 basis point move in yield — key hedging metric
B27: Accrued Interest | C27: =IFERROR(ACCRINT(C7,C7,C8,C9,100,C12,C13),"—") | D27: per 100 face | E27: Interest earned since last coupon date
B28: Net YTM after WHT | C28: =IFERROR(YIELD(C7,C8,C9,C10,100,C12,C13)*(1-C15),"—") | D28: decimal | E28: After-tax return — use this for return comparisons
B29: Real YTM (net of inflation) | C29: =IFERROR(YIELD(C7,C8,C9,C10,100,C12,C13)-C16,"—") | D29: decimal | E29: +ve = you are earning above inflation. -ve = real wealth destruction
B30: Spread vs T-Bill (bps) | C30: =IFERROR((YIELD(C7,C8,C9,C10,100,C12,C13)-CBNRates!C19)*10000,"—") | D30: bps | E30: Yield pickup over 91-day T-bill (risk-free rate)
B31: Spread vs FGN 10Y (bps) | C31: =IFERROR((YIELD(C7,C8,C9,C10,100,C12,C13)-CBNRates!C19)*10000,"—") | D31: bps | E31: Spread over the 10Y FGN benchmark — compensates for tenor / credit risk
B32: Total Coupon Income (₦) | C32: =IFERROR(C9*C11*YEARFRAC(C7,C8,1),"—") | D32: ₦ | E32: Gross coupon cash received from today to maturity (not discounted)
B33: Hold to Mat. Gross Return % | C33: =IFERROR((C9*YEARFRAC(C7,C8,1)*100+(100-C10))/C10,"—") | D33: % | E33: Simple total return if held to maturity (coupon + capital gain/loss)
B34: Signal | C34: =IFERROR(IF(YIELD(C7,C8,C9,C10,100,C12,C13)>C16,"Real yield positive — bond earns above inflation","Real yield negative — bond loses real value"),"—") | E34: Quick verdict on real return viability

Sheet Eurobonds
B2: FGN EUROBOND TRACKER — USD-Denominated Sovereign Debt
B3: Source: DMO Eurobond daily Excel · Data as at: 15 May 2026 · Auto-refreshed: 18 May 2026 18:17
B4: =COUNTA(B7:B17)-COUNTBLANK(B7:B17) | C4: =IFERROR(AVERAGEIF(J7:J17,">0",J7:J17),0) | D4: =IFERROR(SUM(G7:G17),0) | E4: =IFERROR(_xludf.MINIFS(E7:E17,E7:E17,">"&TODAY()),"—")
B5: ACTIVE FGN EUROBONDS · Source: DMO dmo.gov.ng/fgn-bonds/fgn-bond-updates · Update after each weekly DMO publication
B6: Bond / ISIN | C6: Coupon % | D6: Issue Date | E6: Maturity | F6: Tenor (yr) | G6: Amount $B | H6: Bid Price | I6: Ask Price | J6: Mid Yield % | K6: Spread vs UST bps | L6: Rating (Fitch/Moodys)
B7: 6.500% FGN 2027 | C7: 0.065 | D7: 43055 | E7: 46719 | F7: =IFERROR(YEARFRAC(D7,E7,1),"—") | G7: 1.25 | H7: 101.247 | I7: 98.5 | J7: 0.05634 | K7: 320 | L7: B3 / B-
B8: 7.875% FGN 2032 | C8: 0.07875 | D8: 42783 | E8: 48260 | F8: =IFERROR(YEARFRAC(D8,E8,1),"—") | G8: 1.5 | H8: 105.206 | I8: 92.7 | J8: 0.06762 | K8: 420 | L8: B3 / B-
B9: 8.747% FGN 2031 | C9: 0.08747 | D9: 44217 | E9: 47869 | F9: =IFERROR(YEARFRAC(D9,E9,1),"—") | G9: 1.25 | H9: 108.276 | I9: 96.9 | J9: 0.06653 | K9: 430 | L9: B3 / B-
B10: 7.696% FGN 2032 | C10: 0.07696 | D10: 44615 | E10: 48267 | F10: =IFERROR(YEARFRAC(D10,E10,1),"—") | G10: 1.25 | H10: 102.007 | I10: 91.9 | J10: 0.07435 | K10: 425 | L10: B3 / B-
B11: 8.375% FGN 2029 | C11: 0.08375 | D11: 43553 | E11: 47201 | F11: =IFERROR(YEARFRAC(D11,E11,1),"—") | G11: 1.5 | H11: 106.616 | I11: 97.2 | J11: 0.05815 | K11: 390 | L11: B3 / B-
B12: 7.375% FGN 2028 | C12: 0.07375 | D12: 44467 | E12: 47024 | F12: =IFERROR(YEARFRAC(D12,E12,1),"—") | G12: 1.25 | H12: 102.103 | I12: 95.6 | J12: 0.07002 | K12: 360 | L12: B3 / B-
B13: 9.248% FGN 2033 | C13: 0.09248 | D13: 44945 | E13: 48598 | F13: =IFERROR(YEARFRAC(D13,E13,1),"—") | G13: 1.5 | H13: 112.124 | I13: 98.8 | J13: 0.08072 | K13: 440 | L13: B3 / B-
B14: 9.999% FGN 2033 | C14: 0.09999 | D14: 44945 | E14: 48688 | F14: =IFERROR(YEARFRAC(D14,E14,1),"—") | G14: 1.75 | H14: 120.926 | I14: 100.9 | J14: 0.0708 | K14: 490 | L14: B3 / B-
B15: 7.625% FGN 2047 | C15: 0.07625 | D15: 43055 | E15: 54024 | F15: =IFERROR(YEARFRAC(D15,E15,1),"—") | G15: 1.5 | H15: 97.613 | I15: 78 | J15: 0.07856 | K15: 490 | L15: B3 / B-
B16: 8.250% FGN 2051 | C16: 0.0825 | D16: 44467 | E16: 55424 | F16: =IFERROR(YEARFRAC(D16,E16,1),"—") | G16: 1.25 | H16: 101.114 | I16: 79.7 | J16: 0.08144 | K16: 540 | L16: B3 / B-
B17: $4.0B FGN 2030/2034 (Apr 2026) | C17: TBD | D17: 46113 | E17: 47939 | F17: =IFERROR(YEARFRAC(D17,E17,1),"—") | G17: 4 | H17: 113.539 | I17: 100.4 | J17: 0.06458 | K17: TBD | L17: B3 / B-
B19: EUROBOND ANALYTICS — Spread analysis and portfolio metrics
B20: Bond | C20: Mid Yield % | D20: vs 5Y UST bps | E20: vs 10Y UST bps | F20: Days to Mat. | G20: Real Yield (USD) | H20: Bid-Ask Spread | I20: Approx. Price dur. | J20: WHT Applicable | K20: DMO Data URL | L20: Last Updated
B21: =B7 | C21: =J7 | D21: =IFERROR((J7-0.0428)*10000,"—") | E21: =IFERROR((J7-0.0437)*10000,"—") | F21: =IFERROR(E7-TODAY(),"—") | G21: =IFERROR(J7-0.032,"—") | H21: =IFERROR(I7-H7,"—") | I21: =IFERROR(-MDURATION(TODAY(),E7,C7,J7,2,1)*(0.001)*H7,"—") | J21: No (Eurobonds exempt) | K21: dmo.gov.ng/fgn-bonds/fgn-bond-updates | L21: Update weekly from DMO
B22: =B8 | C22: =J8 | D22: =IFERROR((J8-0.0428)*10000,"—") | E22: =IFERROR((J8-0.0437)*10000,"—") | F22: =IFERROR(E8-TODAY(),"—") | G22: =IFERROR(J8-0.032,"—") | H22: =IFERROR(I8-H8,"—") | I22: =IFERROR(-MDURATION(TODAY(),E8,C8,J8,2,1)*(0.001)*H8,"—") | J22: No (Eurobonds exempt) | K22: dmo.gov.ng/fgn-bonds/fgn-bond-updates | L22: Update weekly from DMO
B23: =B9 | C23: =J9 | D23: =IFERROR((J9-0.0428)*10000,"—") | E23: =IFERROR((J9-0.0437)*10000,"—") | F23: =IFERROR(E9-TODAY(),"—") | G23: =IFERROR(J9-0.032,"—") | H23: =IFERROR(I9-H9,"—") | I23: =IFERROR(-MDURATION(TODAY(),E9,C9,J9,2,1)*(0.001)*H9,"—") | J23: No (Eurobonds exempt) | K23: dmo.gov.ng/fgn-bonds/fgn-bond-updates | L23: Update weekly from DMO
B24: =B10 | C24: =J10 | D24: =IFERROR((J10-0.0428)*10000,"—") | E24: =IFERROR((J10-0.0437)*10000,"—") | F24: =IFERROR(E10-TODAY(),"—") | G24: =IFERROR(J10-0.032,"—") | H24: =IFERROR(I10-H10,"—") | I24: =IFERROR(-MDURATION(TODAY(),E10,C10,J10,2,1)*(0.001)*H10,"—") | J24: No (Eurobonds exempt) | K24: dmo.gov.ng/fgn-bonds/fgn-bond-updates | L24: Update weekly from DMO
B25: =B11 | C25: =J11 | D25: =IFERROR((J11-0.0428)*10000,"—") | E25: =IFERROR((J11-0.0437)*10000,"—") | F25: =IFERROR(E11-TODAY(),"—") | G25: =IFERROR(J11-0.032,"—") | H25: =IFERROR(I11-H11,"—") | I25: =IFERROR(-MDURATION(TODAY(),E11,C11,J11,2,1)*(0.001)*H11,"—") | J25: No (Eurobonds exempt) | K25: dmo.gov.ng/fgn-bonds/fgn-bond-updates | L25: Update weekly from DMO
B26: =B12 | C26: =J12 | D26: =IFERROR((J12-0.0428)*10000,"—") | E26: =IFERROR((J12-0.0437)*10000,"—") | F26: =IFERROR(E12-TODAY(),"—") | G26: =IFERROR(J12-0.032,"—") | H26: =IFERROR(I12-H12,"—") | I26: =IFERROR(-MDURATION(TODAY(),E12,C12,J12,2,1)*(0.001)*H12,"—") | J26: No (Eurobonds exempt) | K26: dmo.gov.ng/fgn-bonds/fgn-bond-updates | L26: Update weekly from DMO
B27: =B13 | C27: =J13 | D27: =IFERROR((J13-0.0428)*10000,"—") | E27: =IFERROR((J13-0.0437)*10000,"—") | F27: =IFERROR(E13-TODAY(),"—") | G27: =IFERROR(J13-0.032,"—") | H27: =IFERROR(I13-H13,"—") | I27: =IFERROR(-MDURATION(TODAY(),E13,C13,J13,2,1)*(0.001)*H13,"—") | J27: No (Eurobonds exempt) | K27: dmo.gov.ng/fgn-bonds/fgn-bond-updates | L27: Update weekly from DMO
B28: =B14 | C28: =J14 | D28: =IFERROR((J14-0.0428)*10000,"—") | E28: =IFERROR((J14-0.0437)*10000,"—") | F28: =IFERROR(E14-TODAY(),"—") | G28: =IFERROR(J14-0.032,"—") | H28: =IFERROR(I14-H14,"—") | I28: =IFERROR(-MDURATION(TODAY(),E14,C14,J14,2,1)*(0.001)*H14,"—") | J28: No (Eurobonds exempt) | K28: dmo.gov.ng/fgn-bonds/fgn-bond-updates | L28: Update weekly from DMO
B29: =B15 | C29: =J15 | D29: =IFERROR((J15-0.0428)*10000,"—") | E29: =IFERROR((J15-0.0437)*10000,"—") | F29: =IFERROR(E15-TODAY(),"—") | G29: =IFERROR(J15-0.032,"—") | H29: =IFERROR(I15-H15,"—") | I29: =IFERROR(-MDURATION(TODAY(),E15,C15,J15,2,1)*(0.001)*H15,"—") | J29: No (Eurobonds exempt) | K29: dmo.gov.ng/fgn-bonds/fgn-bond-updates | L29: Update weekly from DMO
B30: =B16 | C30: =J16 | D30: =IFERROR((J16-0.0428)*10000,"—") | E30: =IFERROR((J16-0.0437)*10000,"—") | F30: =IFERROR(E16-TODAY(),"—") | G30: =IFERROR(J16-0.032,"—") | H30: =IFERROR(I16-H16,"—") | I30: =IFERROR(-MDURATION(TODAY(),E16,C16,J16,2,1)*(0.001)*H16,"—") | J30: No (Eurobonds exempt) | K30: dmo.gov.ng/fgn-bonds/fgn-bond-updates | L30: Update weekly from DMO
B31: =B17 | C31: =J17 | D31: =IFERROR((J17-0.0428)*10000,"—") | E31: =IFERROR((J17-0.0437)*10000,"—") | F31: =IFERROR(E17-TODAY(),"—") | G31: =IFERROR(J17-0.032,"—") | H31: =IFERROR(I17-H17,"—") | I31: =IFERROR(-MDURATION(TODAY(),E17,C17,J17,2,1)*(0.001)*H17,"—") | J31: No (Eurobonds exempt) | K31: dmo.gov.ng/fgn-bonds/fgn-bond-updates | L31: Update weekly from DMO
